Workbook

Sheet 總課表
A1: 2026 目標半馬賽事
A2: Race Date | C2: 46355 | F2: Project Half | G2: 目標時間 | H2: =配速表!$B$2
A3: 完成 | B3: 周次 | C3: 日期 | D3: 星期 | E3: 課表類型 | F3: 課表內容 | G3: 公里數 | H3: 備註 | I3: 單周跑量
B4: 1 | C4: =C5-1 | D4: =C4 | E4: 休息日 | I4: =SUM(G4:G10)
C5: =C6-1 | D5: =C5 | E5: 休息日 | L5: 輕鬆有氧 | M5: 長跑 | N5: 節奏跑 | O5: 強化跑 | P5: 速度跑 | Q5: 休息日
C6: =C7-1 | D6: =C6 | E6: 休息日 | K6: 配速 | L6: =TEXT(INDEX(配速表!$D$5:$D$21,MATCH(配速表!$B$2,配速表!$B$5:$B$21,0)),"m:ss")&"~"&TEXT(INDEX(配速表!$E$5:$E$21,MATCH(配速表!$B$2,配速表!$B$5:$B$21,0)),"m:ss") | M6: =INDEX(配速表!$F$5:$F$21,MATCH(配速表!$B$2,配速表!$B$5:$B$21,0)) | N6: =INDEX(配速表!$G$5:$G$21,MATCH(配速表!$B$2,配速表!$B$5:$B$21,0)) | O6: =INDEX(配速表!$H$5:$H$21,MATCH(配速表!$B$2,配速表!$B$5:$B$21,0)) | P6: =ROUND(INDEX(配速表!$Q$5:$Q$21,MATCH(配速表!$B$2,配速表!$B$5:$B$21,0))*86400,0)&"s/lap" | Q6: —
C7: =C8-1 | D7: =C7 | E7: 輕鬆有氧 | F7: 6k Easy | G7: 6
C8: =C9-1 | D8: =C8 | E8: 輕鬆有氧 | F8: 5k Easy | G8: 5 | L8: 注意事項
C9: =C10-1 | D9: =C9 | E9: 輕鬆有氧 | F9: 6k Easy | G9: 6 | L9: ● 修改Race Date可以同步調整每個課表的日期
C10: =C11-1 | D10: =C10 | E10: 輕鬆有氧 | F10: 10k Easy | G10: 10 | L10: ● 參照訓練配速表可以知道各個課表的速度
B11: =B4+1 | C11: =C12-1 | D11: =C11 | E11: 輕鬆有氧 | F11: 6k Easy | G11: 6 | I11: =SUM(G11:G17) | L11: ● 如果跑量無法這麼高，可以等比例降低每個課表的長度
C12: =C13-1 | D12: =C12 | E12: 速度跑 | F12: 2k WU+12x(400m@5-10k pace+400m jog rest)+2k CD | G12: 13.6 | L12: ● 公里數計法：暖身+主課表+收操（不含組間恢復跑）
C13: =C14-1 | D13: =C13 | E13: 休息日
C14: =C15-1 | D14: =C14 | E14: 節奏跑 | F14: 2k WU+5k Tempo@HMP+2k CD | G14: 9
C15: =C16-1 | D15: =C15 | E15: 輕鬆有氧 | F15: 6k Easy | G15: 6
C16: =C17-1 | D16: =C16 | E16: 輕鬆有氧 | F16: 6k Easy | G16: 6
C17: =C18-1 | D17: =C17 | E17: 輕鬆有氧 | F17: 10k Easy | G17: 10
B18: =B11+1 | C18: =C19-1 | D18: =C18 | E18: 輕鬆有氧 | F18: 6k Easy | G18: 6 | I18: =SUM(G18:G24)
C19: =C20-1 | D19: =C19 | E19: 速度跑 | F19: 2k WU+8x(600m@5-10k pace+400m jog rest)+2k CD | G19: 12
C20: =C21-1 | D20: =C20 | E20: 休息日
C21: =C22-1 | D21: =C21 | E21: 節奏跑 | F21: 2k WU+5k Tempo@HMP+2k CD | G21: 9
C22: =C23-1 | D22: =C22 | E22: 輕鬆有氧 | F22: 8k Easy | G22: 8
C23: =C24-1 | D23: =C23 | E23: 輕鬆有氧 | F23: 8k Easy | G23: 8
C24: =C25-1 | D24: =C24 | E24: 輕鬆有氧 | F24: 11k Easy | G24: 11
B25: =B18+1 | C25: =C26-1 | D25: =C25 | E25: 輕鬆有氧 | F25: 8k Easy | G25: 8 | I25: =SUM(G25:G31)
C26: =C27-1 | D26: =C26 | E26: 速度跑 | F26: 2k WU+6x(800m@5-10k pace+400m jog rest)+2k CD | G26: 11.2
C27: =C28-1 | D27: =C27 | E27: 休息日
C28: =C29-1 | D28: =C28 | E28: 節奏跑 | F28: 2k WU+5k Tempo@HMP+2k CD | G28: 9
C29: =C30-1 | D29: =C29 | E29: 輕鬆有氧 | F29: 6k Easy | G29: 6
C30: =C31-1 | D30: =C30 | E30: 輕鬆有氧 | F30: 10k Easy | G30: 10
C31: =C32-1 | D31: =C31 | E31: 輕鬆有氧 | F31: 13k Easy | G31: 13
B32: =B25+1 | C32: =C33-1 | D32: =C32 | E32: 輕鬆有氧 | F32: 6k Easy | G32: 6 | I32: =SUM(G32:G38)
C33: =C34-1 | D33: =C33 | E33: 速度跑 | F33: 2k WU+5x(1000m@5-10k pace+600m jog rest)+2k CD | G33: 12
C34: =C35-1 | D34: =C34 | E34: 休息日
C35: =C36-1 | D35: =C35 | E35: 節奏跑 | F35: 2k WU+6k Tempo@HMP+2k CD | G35: 10
C36: =C37-1 | D36: =C36 | E36: 輕鬆有氧 | F36: 8k Easy | G36: 8
C37: =C38-1 | D37: =C37 | E37: 輕鬆有氧 | F37: 10k Easy | G37: 10
C38: =C39-1 | D38: =C38 | E38: 長跑 | F38: 16k Long run | G38: 16
B39: =B32+1 | C39: =C40-1 | D39: =C39 | E39: 輕鬆有氧 | F39: 8k Easy | G39: 8 | I39: =SUM(G39:G45)
C40: =C41-1 | D40: =C40 | E40: 速度跑 | F40: 2k WU+4x(1200m@5-10k pace+600m jog rest)+2k CD | G40: 11.2
...

Sheet 配速表
A1: 🎯 漢森半馬課表配速表 — 在下方 B2 儲存格選擇你的半馬目標，整份總課表的配速會自動同步
A2: 目標時間 → | B2: 0.0625 | C2: ← 點擊此儲存格右側的下拉箭頭，選擇你的目標成績
A4: 選取 | B4: 半馬目標時間 | C4: 恢復跑 | D4: 輕鬆有氧A | E4: 輕鬆有氧B | F4: 長跑 | G4: 節奏跑(HMP) | H4: 強化跑(10K配速) | I4: 5公里配速 | J4: 預估10K PB | K4: 預估5K PB | L4: 1600公尺配速 | M4: 1200公尺配速 | N4: 1000公尺配速 | O4: 800公尺配速 | P4: 600公尺配速 | Q4: 400公尺配速
A5: =IF($B5=$B$2,"▶","") | B5: 0.10416667 | C5: 0.0059953704 | D5: 0.005787037 | E5: 0.0055671296 | F5: 0.0054166667 | G5: 0.0049305556 | H5: 0.0047106481 | I5: 0.004525463 | J5: =H5*10 | K5: =I5*5 | L5: =K5/5*1.6 | M5: =K5/5*1.2 | N5: =K5/5 | O5: =K5/5*0.8 | P5: =K5/5*0.6 | Q5: =K5/5*0.4
A6: =IF($B6=$B$2,"▶","") | B6: 0.10069444 | C6: 0.0058333333 | D6: 0.0056134259 | E6: 0.0053935185 | F6: 0.0052430556 | G6: 0.0047685185 | H6: 0.0045601852 | I6: 0.004375 | J6: =H6*10 | K6: =I6*5 | L6: =K6/5*1.6 | M6: =K6/5*1.2 | N6: =K6/5 | O6: =K6/5*0.8 | P6: =K6/5*0.6 | Q6: =K6/5*0.4
A7: =IF($B7=$B$2,"▶","") | B7: 0.097222222 | C7: 0.0056712963 | D7: 0.0054513889 | E7: 0.0052314815 | F7: 0.0050810185 | G7: 0.0046064815 | H7: 0.0043981481 | I7: 0.004224537 | J7: =H7*10 | K7: =I7*5 | L7: =K7/5*1.6 | M7: =K7/5*1.2 | N7: =K7/5 | O7: =K7/5*0.8 | P7: =K7/5*0.6 | Q7: =K7/5*0.4
A8: =IF($B8=$B$2,"▶","") | B8: 0.09375 | C8: 0.0054861111 | D8: 0.0052777778 | E8: 0.0050578704 | F8: 0.0049074074 | G8: 0.0044328704 | H8: 0.0042476852 | I8: 0.0040740741 | J8: =H8*10 | K8: =I8*5 | L8: =K8/5*1.6 | M8: =K8/5*1.2 | N8: =K8/5 | O8: =K8/5*0.8 | P8: =K8/5*0.6 | Q8: =K8/5*0.4
A9: =IF($B9=$B$2,"▶","") | B9: 0.090277778 | C9: 0.0053240741 | D9: 0.0051041667 | E9: 0.0048842593 | F9: 0.0047337963 | G9: 0.0042708333 | H9: 0.0040856481 | I9: 0.0039236111 | J9: =H9*10 | K9: =I9*5 | L9: =K9/5*1.6 | M9: =K9/5*1.2 | N9: =K9/5 | O9: =K9/5*0.8 | P9: =K9/5*0.6 | Q9: =K9/5*0.4
A10: =IF($B10=$B$2,"▶","") | B10: 0.086805556 | C10: 0.0051388889 | D10: 0.0049305556 | E10: 0.0047106481 | F10: 0.0045601852 | G10: 0.0041087963 | H10: 0.0039236111 | I10: 0.0037731481 | J10: =H10*10 | K10: =I10*5 | L10: =K10/5*1.6 | M10: =K10/5*1.2 | N10: =K10/5 | O10: =K10/5*0.8 | P10: =K10/5*0.6 | Q10: =K10/5*0.4
A11: =IF($B11=$B$2,"▶","") | B11: 0.083333333 | C11: 0.0049768519 | D11: 0.0047569444 | E11: 0.004537037 | F11: 0.0043865741 | G11: 0.0039467593 | H11: 0.0037731481 | I11: 0.0036226852 | J11: =H11*10 | K11: =I11*5 | L11: =K11/5*1.6 | M11: =K11/5*1.2 | N11: =K11/5 | O11: =K11/5*0.8 | P11: =K11/5*0.6 | Q11: =K11/5*0.4
A12: =IF($B12=$B$2,"▶","") | B12: 0.079861111 | C12: 0.0047916667 | D12: 0.0045833333 | E12: 0.0043634259 | F12: 0.004212963 | G12: 0.0037847222 | H12: 0.0036111111 | I12: 0.0034606481 | J12: =H12*10 | K12: =I12*5 | L12: =K12/5*1.6 | M12: =K12/5*1.2 | N12: =K12/5 | O12: =K12/5*0.8 | P12: =K12/5*0.6 | Q12: =K12/5*0.4
A13: =IF($B13=$B$2,"▶","") | B13: 0.076388889 | C13: 0.0046296296 | D13: 0.0044212963 | E13: 0.0042013889 | F13: 0.0040509259 | G13: 0.0036111111 | H13: 0.0034606481 | I13: 0.0033101852 | J13: =H13*10 | K13: =I13*5 | L13: =K13/5*1.6 | M13: =K13/5*1.2 | N13: =K13/5 | O13: =K13/5*0.8 | P13: =K13/5*0.6 | Q13: =K13/5*0.4
A14: =IF($B14=$B$2,"▶","") | B14: 0.072916667 | C14: 0.0044675926 | D14: 0.0042476852 | E14: 0.0040277778 | F14: 0.0038773148 | G14: 0.0034490741 | H14: 0.0032986111 | I14: 0.0031597222 | J14: =H14*10 | K14: =I14*5 | L14: =K14/5*1.6 | M14: =K14/5*1.2 | N14: =K14/5 | O14: =K14/5*0.8 | P14: =K14/5*0.6 | Q14: =K14/5*0.4
A15: =IF($B15=$B$2,"▶","") | B15: 0.069444444 | C15: 0.0042824074 | D15: 0.0040740741 | E15: 0.0038541667 | F15: 0.0037037037 | G15: 0.003287037 | H15: 0.0031365741 | I15: 0.0030092593 | J15: =H15*10 | K15: =I15*5 | L15: =K15/5*1.6 | M15: =K15/5*1.2 | N15: =K15/5 | O15: =K15/5*0.8 | P15: =K15/5*0.6 | Q15: =K15/5*0.4
A16: =IF($B16=$B$2,"▶","") | B16: 0.065972222 | C16: 0.0041203704 | D16: 0.003900463 | E16: 0.0036805556 | F16: 0.0035300926 | G16: 0.003125 | H16: 0.0029861111 | I16: 0.0028587963 | J16: =H16*10 | K16: =I16*5 | L16: =K16/5*1.6 | M16: =K16/5*1.2 | N16: =K16/5 | O16: =K16/5*0.8 | P16: =K16/5*0.6 | Q16: =K16/5*0.4
... A21: =IF($B21=$B$2,"▶","") | B21: 0.048611111 | C21: 0.0032638889 | D21: 0.0030439815 | E21: 0.0028240741 | F21: 0.0026736111 | G21: 0.0023032407 | H21: 0.0021990741 | I21: 0.0021064815 | J21: =H21*10 | K21: =I21*5 | L21: =K21/5*1.6 | M21: =K21/5*1.2 | N21: =K21/5 | O21: =K21/5*0.8 | P21: =K21/5*0.6 | Q21: =K21/5*0.4
A23: 配速來源：Hansons官方計算機 lukehumphreyrunning.com/hmmcalculator（2026-07取樣）；強化跑=10K等效配速（原書半馬課表第11-17週設定）

Sheet 課表重點
A4: 速度跑 | H4: 術語解說
A5: ● 以5公里及10公里跑步表現作為依據，配速介於80~95%的最大攝氧量間 | H5: 2k WU+12x(400m@5-10k pace+400m jog rest)+2k CD
A6: ● 課表原則是逐步增加，本周400m一組，下周800m，達到2000m後再逐步下修 | H6: 2k WU代表2公里暖身(Warm up, WU),速度參照配速表中的恢復跑即可
A7: ● 組間可以使用輕鬆跑作為動態恢復或是停下來休息都可，研究顯示差別不大 | H7: 12x(400m@5-10k pace+400m jog rest)
A8: ● 休息時間大約是每組的50~100%，比如400m跑80秒，則組間休40~80秒皆可 | H8: 代表每組400m，以5-10k目標配速的速度跑，組間用400m的輕鬆跑作為動態恢復
H9: 2k CD代表以2公里緩和(Cool down, CD)作為收操
A11: 輕鬆跑 | H11: HMP: Half Marathon Pace 半馬比賽配速
A12: ● 跑步持續時間介於20分鐘~2.5小時 | H12: 強化跑: 第11-17週以10K配速進行（見配速表）
A13: ● 強度維持在最大攝氧量55~75%，或約等於相較比賽配速每公里慢37.5~75秒
A14: ● 輕鬆跑可以分為(B)快速(每公里慢37.5秒)或(A)慢速(每公里慢75秒) | H14: 訓練日調換原則
A15: ● 課表中的暖身或收操可以慢速輕鬆跑進行，也適合安排在強度訓練的隔天 | H15: 如果跑步課表需要配合日常行程變動，則依據以下原則
A16: ● 更進階的跑者在強度訓練的前一天也可進行快速輕鬆跑 | H16: ● 不要連續兩天安排素質練習(速度跑、節奏跑)
A17: ● 輕鬆跑是漢森課表的主要訓練元素，如果想要提升課表整體強度，可以先從增加輕鬆跑跑量開始 | H17: ● 每周兩次的素質訓練可以間隔天數拉長，中間以輕鬆跑代替
H18: ● 若一周要休兩次，盡量休在兩個素質訓練的中間
A19: 長跑 | H19: ● 長跑前一天不要全休
A20: ● 速度必須比輕鬆跑更快，跑起來的體感不能與輕鬆跑一樣輕鬆
A21: ● 訓練目的是：模擬半馬比賽後段的疲勞程度。故不會在長跑前一天全休
A22: ● 長跑不超過每周跑量的25~30%，時間應控制在2.5~3小時
A23: ● 若恢復不佳，可以減少訓練長度，但不要降低訓練速度
A25: 節奏跑
A26: ● 就是半馬比賽配速跑（HMP）
A27: ● 全程穩定配速是關鍵，特別是絕對不要前段快後段慢(positive split)
A28: ● 不要停下來
